Workbook

Sheet README
B1: Client Environment Review - Assessment Workbook
B2: v1.1 - 5 Sep 2026 - blueAPACHE Portfolio Engineering (Bikash Shrestha). Companion to 'Client-Environment-Review-Method-and-Report-Template.docx'.
B4: What this is
B5: Purpose | C5: A repeatable, scored review of one client environment across 11 domains (124 controls) to find gaps, risks and improvement/billable opportunities. One workbook per client per review. Internal working tool - the client-ready output is the .docx report.
B6: Discharges (PE Handbook) | C6: Priority 5 (risks -> SDM & CAM), 13 (quarterly BAMS inclusions review), 14 (documentation currency), 15 (billable items -> eFO leads), quarterly technology/M365 health reporting (top-3 per customer per quarter).
B7: Baseline | C7: Security domains score against ACSC/ASD Essential Eight ML1 (target 2) with ML2 as 'optimised' (3). Other domains use vendor / bA best-practice checklists. E8 model version: last updated 27 Nov 2023 (cyber.gov.au), confirmed current 5 Sep 2026.
B9: How to run a review (about half a day for a baseline; 1-2 h for a quarterly refresh)
B10: 1. Client tab | C10: Fill the yellow cells. Mark domains out of scope. Note the E8 target agreed (or 'none yet').
B11: 2. Prep (30 min) | C11: Load PROFILE / STACK / COMMITMENTS / PROBLEMS / OPPORTUNITIES for the client, the last quarterly report, the BAMS inclusions PowerBI extract, and open the consoles you have access to (Lighthouse, Orion, N-Central, Veeam/vminfo, FortiManager, EDR, Huntress/Rapid7, SNOW).
B12: 3. Score (2-3 h) | C12: Checklist tab: for each control set Score (0-3 or N/A) using the rubric; record what you saw in 'Current state / evidence'. Unknown = 0 and a note. Skip nothing - N/A is a decision, blank is not.
B13: 4. Rate gaps | C13: For every row showing 'Gap': set Risk (H/M/L), Effort (S/M/L), confirm the Tag (BAU / Billable / Value-add / Client-owned), write a one-line Recommendation and an Owner. Priority and Quick-win compute automatically.
B14: 5. Read the roll-ups | C14: Summary = domain scorecard + Essential Eight indicative maturity + gap counts by tag. Findings = top 20 gaps ranked, plus the Top-3 for the quarter you choose. Roadmap = 30/90/180-day plan by ID.
B15: 6. Validate with the SDM (30 min) | C15: Scope, politics, what the client already knows, what is in flight. Adjust risk ratings; agree the Top-3.
B16: 7. File it | C16: Set 'Filed to' + Ref per gap: OPPORTUNITIES.md (business consequence), STACK debt register / verification backlog, PROBLEMS.md, SNOW ticket, eFO lead via SDM, or Risk notified (SDM+CAM). High risks must be notified in writing.
B17: 8. Write up | C17: Use the .docx template (Part B). Real client names only when the SDM confirms it is going out. This workbook holds identifiers - keep it local; sanitise per the client's sanitiser map before pasting anywhere.
B18: 9. Portfolio | C18: Copy the Summary 'Export strip' and the Checklist 'GapFlag' column into the master Portfolio tab for pattern hunting. A gap at 3+ clients is a service offering, not a client problem - raise with Head of PE / Presales.
B19: Quarterly refresh | C19: Re-score only: rows that were gaps, all COV rows, anything that changed (LOG.md), plus any control whose 'Last reviewed' is older than 6 months. Full pass annually or on handover / contract renewal / major incident.
B21: Scoring rubric
B22: 0 | C22: Absent or unknown - not implemented, or no evidence could be found. Unknown scores 0 until evidenced.
B23: 1 | C23: Partial or ad hoc - implemented for part of the scope, undocumented, unverified, or relies on one person.
B24: 2 | C24: Implemented and consistent - meets the target state across the in-scope estate; evidence sighted; documented. (Baseline / ~E8 ML1 where mapped)
B25: 3 | C25: Optimised - exceeds baseline, monitored and alerted, reviewed on a cadence, documented and owned. (~E8 ML2 where mapped - verify formally)
B26: N/A | C26: Not applicable to this client (e.g. no Azure, no on-prem AD). Excluded from percentages. Say why in the notes column.
B27: Target score | C27: Default 2 for every control (baseline). Raise to 3 for tier-1 systems or regulated clients; lower only with a documented reason. Gap = Score < Target.
B29: Priority (Risk x Effort) and tags
B30: Priority | C30: H+S=P1, H+M=P1, H+L=P2, M+S=P2, M+M=P2, M+L=P3, L+S=P3, L+M=P3, L+L=P4. Quick win = Gap with Effort S and Risk H or M. Risk is business consequence x likelihood in this client's context, not generic severity.
B31: BAU | C31: bA should already be delivering this under BAMS. A BAU gap is a service-delivery issue - fix it, do not sell it. Raise a SNOW ticket / Catalogue Task.
B32: Billable | C32: Out of BAMS scope; remediation is project or T&M work -> eFO lead via SDM (handbook: agreed remediation from technology reports is billable).
B33: Value-add | C33: Advice or a small fix done within the relationship. Builds trust; note the time in the Proactive subtask.
B34: Client-owned | C34: The client's responsibility (policy, budget, their vendor). bA advises and records the risk decision.
B36: Colour legend
B37: Yellow fill / blue text | C37: Input cells - you fill these.
B38: White, black text | C38: Formulas - leave alone. Hidden helper columns (RankKey, Attained, E8 *) feed Summary/Findings; do not delete.
B39: Green fill | C39: Tool status / Tool evidence - filled automatically from the AutoEvidence tab (CER-Discovery output). Read it, then write your own Current state line and score.
B40: Score cell colours | C40: 0 red, 1 orange, 2 light green, 3 green, N/A grey. Priority P1 red, P2 orange. RAG: Green >= 80% of target, Amber >= 50%, Red below (thresholds on Lists tab).
B42: Example of a completed row (format only - not real data)
B43: ID | C43: BDR-04
B44: Score | C44: 1 (partial - second copy exists but is not protected)
B45: Risk / Effort | C45: H / M -> Priority P1 (computed)
B46: Tag | C46: Billable
...

Sheet Client
B1: Client and review details
B2: Yellow cells are inputs. This sheet may hold real client identifiers - keep local; sanitise before sharing (sanitiser-maps/<alias>.json).
B4: Field | C4: Value | E4: Domain | F4: In scope? | G4: Scope note
B5: Client code | C5: C-0XX | E5: IAM - Identity & Access | F5: Yes
B6: Client alias | E6: M365 - Microsoft 365 & Email Security | F6: Yes
B7: Client name (real - local only) | E7: END - Endpoint | F7: Yes
B8: Sector / obligations | E8: SRV - Servers & Virtualisation | F8: Yes
B9: SDM | E9: NET - Network & Firewall | F9: Yes
B10: CAM / AM | E10: BDR - Backup & DR | F10: Yes
B11: Reviewer | C11: Bikash Shrestha | E11: COV - Monitoring, Patching & BAMS Coverage | F11: Yes
B12: Review date | C12: 46270 | E12: SEC - Security Programme & Essential Eight | F12: Yes
B13: Review type | C13: Baseline | E13: AZ - Azure & Cloud | F13: Yes
B14: Next review due | C14: =IF(ISNUMBER(C11),C11+91,"") | E14: DOC - Documentation & Operational Hygiene | F14: Yes
B15: Contract (BAMS tier / SoW ref) | E15: LIC - Lifecycle, Licensing & Commercial | F15: Yes
B16: Users (approx.)
B17: Sites | E17: If 'No': set every control in that domain to N/A on the Checklist so percentages exclude it.
B18: Servers (on-prem / emPOWER / Azure)
B19: M365 tenant(s) | E19: Evidence pulled (tick) | F19: Done | G19: Where / date
B20: Identity posture | C20: Hybrid - Entra Connect | E20: Client flow files (PROFILE/STACK/LOG/COMMITMENTS/PROBLEMS/OPPORTUNITIES)
B21: Security stack (EDR / MDR / gateway / app control) | E21: BAMS inclusions PowerBI extract
B22: Backup platform(s) | E22: Last quarterly / M365 health report
B23: Firewall / network platform | E23: Secure Score + Defender report
B24: Essential Eight target agreed | C24: None agreed | E24: Orion node list / N-Central patch + OS reports
B25: Last quarterly report date | E25: Veeam / vminfo backup status
B26: Notes / context from SDM | E26: FortiManager firmware + policy export
E27: EDR + Huntress/Rapid7 coverage
E28: SNOW: CIs, 90-day incidents, open problems
E29: Lifecycle lookups (MS Lifecycle, vendor EoS, warranty)

Sheet Checklist
A1: Client Environment Review - Checklist (v1.2)
A2: Score every row (0-3 or N/A). For each 'Gap' set Risk, Effort, Tag, Recommendation, Owner, Filed to. Yellow = input; green = pulled from the AutoEvidence tab (CER-Discovery). Hidden helper columns feed the roll-ups - do not delete. Filter by Dom to work one domain at a time.
A4: ID | B4: Dom | C4: Domain | D4: Control / check | E4: Why it matters | F4: Evidence source (bA tools) | G4: How to check | H4: Target state (baseline = score 2) | I4: E8 map | J4: Typical tag | K4: Target score | L4: Score (0-3 / N/A) | M4: Gap? | N4: Risk (H/M/L) | O4: Effort (S/M/L) | P4: Priority | Q4: Quick win | R4: Tag | S4: Tool status (auto) | T4: Tool evidence (auto, from CER-Discovery via AutoEvidence tab) | U4: Current state / evidence (what you saw, where, when) | V4: Recommendation | W4: Owner | X4: Filed to | Y4: Ref (ticket / lead / row) | Z4: Source tag | AA4: Last reviewed | AB4: GapFlag (copy to Portfolio) | AC4: RankKey | AD4: Attained | AE4: E8 PA | AF4: E8 PO | AG4: E8 MFA | AH4: E8 RAP | AI4: E8 AC | AJ4: E8 MAC | AK4: E8 UAH | AL4: E8 RB
A5: IAM-01 | B5: IAM | C5: Identity & Access | D5: Identity architecture documented and healthy (cloud-only / hybrid; Entra Connect or Cloud Sync; sync status) | E5: Everything else in identity depends on knowing where the source of truth is and that sync is not silently broken. | F5: Entra admin centre (via M365 Lighthouse) > Entra Connect / Cloud Sync health; STACK.md | G5: Confirm sync type and server, last sync < 1 h, zero export errors, staging server present or absence noted. Record in STACK.md. | H5: Documented in STACK.md; sync healthy; owner of the sync server known. | J5: BAU | K5: 2 | M5: =IF(ISNUMBER(L5),IF(L5<K5,"Gap","OK"),IF(L5="N/A","N/A","")) | P5: =IF(AND(M5="Gap",N5<>"",O5<>""),VLOOKUP(N5&O5,Lists!$H$4:$I$12,2,FALSE()),"") | Q5: =IF(AND(M5="Gap",O5="S",OR(N5="H",N5="M")),"Yes","") | R5: BAU | S5: =IF(A5="","",IFERROR(IF(OR(VLOOKUP(A5,AutoEvidence!$A$2:$G$400,2,FALSE())="Collected",VLOOKUP(A5,AutoEvidence!$A$2:$G$400,2,FALSE())="Partial"),VLOOKUP(A5,AutoEvidence!$A$2:$G$400,3,FALSE())&" ("&VLOOKUP(A5,AutoEvidence!$A$2:$G$400,2,FALSE())&")",VLOOKUP(A5,AutoEvidence!$A$2:$G$400,2,FALSE())),"")) | T5: =IF(A5="","",IFERROR(VLOOKUP(A5,AutoEvidence!$A$2:$G$400,4,FALSE())&"","")) | AB5: =IF(M5="Gap",1,IF(M5="OK",0,"")) | AC5: =IF(P5<>"",VALUE(RIGHT(P5,1))*1000+ROW(),"") | AD5: =IF(ISNUMBER(L5),MIN(L5,K5),"") | AE5: =IF(AND(ISNUMBER(SEARCH(" PA "," "&SUBSTITUTE($I5,","," ")&" ")),ISNUMBER($L5)),$L5,"") | AF5: =IF(AND(ISNUMBER(SEARCH(" PO "," "&SUBSTITUTE($I5,","," ")&" ")),ISNUMBER($L5)),$L5,"") | AG5: =IF(AND(ISNUMBER(SEARCH(" MFA "," "&SUBSTITUTE($I5,","," ")&" ")),ISNUMBER($L5)),$L5,"") | AH5: =IF(AND(ISNUMBER(SEARCH(" RAP "," "&SUBSTITUTE($I5,","," ")&" ")),ISNUMBER($L5)),$L5,"") | AI5: =IF(AND(ISNUMBER(SEARCH(" AC "," "&SUBSTITUTE($I5,","," ")&" ")),ISNUMBER($L5)),$L5,"") | AJ5: =IF(AND(ISNUMBER(SEARCH(" MAC "," "&SUBSTITUTE($I5,","," ")&" ")),ISNUMBER($L5)),$L5,"") | AK5: =IF(AND(ISNUMBER(SEARCH(" UAH "," "&SUBSTITUTE($I5,","," ")&" ")),ISNUMBER($L5)),$L5,"") | AL5: =IF(AND(ISNUMBER(SEARCH(" RB "," "&SUBSTITUTE($I5,","," ")&" ")),ISNUMBER($L5)),$L5,"")
A6: IAM-02 | B6: IAM | C6: Identity & Access | D6: MFA enforced for all users via Conditional Access (not legacy per-user MFA); registration coverage | E6: Commodity credential attacks are the #1 initial access path (E8 ML1 MFA). | F6: Entra > Conditional Access; Entra > Authentication methods > Registration report; Lighthouse 'Users without MFA' | G6: Policy requiring MFA for all users is On (not report-only); exclusions limited to break-glass and reviewed; % registered = 100%; no Security Defaults/per-user mix. | H6: 100% of enabled users registered and enforced through CA; exclusions documented. | I6: MFA | J6: BAU | K6: 2 | M6: =IF(ISNUMBER(L6),IF(L6<K6,"Gap","OK"),IF(L6="N/A","N/A","")) | P6: =IF(AND(M6="Gap",N6<>"",O6<>""),VLOOKUP(N6&O6,Lists!$H$4:$I$12,2,FALSE()),"") | Q6: =IF(AND(M6="Gap",O6="S",OR(N6="H",N6="M")),"Yes","") | R6: BAU | S6: =IF(A6="","",IFERROR(IF(OR(VLOOKUP(A6,AutoEvidence!$A$2:$G$400,2,FALSE())="Collected",VLOOKUP(A6,AutoEvidence!$A$2:$G$400,2,FALSE())="Partial"),VLOOKUP(A6,AutoEvidence!$A$2:$G$400,3,FALSE())&" ("&VLOOKUP(A6,AutoEvidence!$A$2:$G$400,2,FALSE())&")",VLOOKUP(A6,AutoEvidence!$A$2:$G$400,2,FALSE())),"")) | T6: =IF(A6="","",IFERROR(VLOOKUP(A6,AutoEvidence!$A$2:$G$400,4,FALSE())&"","")) | AB6: =IF(M6="Gap",1,IF(M6="OK",0,"")) | AC6: =IF(P6<>"",VALUE(RIGHT(P6,1))*1000+ROW(),"") | AD6: =IF(ISNUMBER(L6),MIN(L6,K6),"") | AE6: =IF(AND(ISNUMBER(SEARCH(" PA "," "&SUBSTITUTE($I6,","," ")&" ")),ISNUMBER($L6)),$L6,"") | AF6: =IF(AND(ISNUMBER(SEARCH(" PO "," "&SUBSTITUTE($I6,","," ")&" ")),ISNUMBER($L6)),$L6,"") | AG6: =IF(AND(ISNUMBER(SEARCH(" MFA "," "&SUBSTITUTE($I6,","," ")&" ")),ISNUMBER($L6)),$L6,"") | AH6: =IF(AND(ISNUMBER(SEARCH(" RAP "," "&SUBSTITUTE($I6,","," ")&" ")),ISNUMBER($L6)),$L6,"") | AI6: =IF(AND(ISNUMBER(SEARCH(" AC "," "&SUBSTITUTE($I6,","," ")&" ")),ISNUMBER($L6)),$L6,"") | AJ6: =IF(AND(ISNUMBER(SEARCH(" MAC "," "&SUBSTITUTE($I6,","," ")&" ")),ISNUMBER($L6)),$L6,"") | AK6: =IF(AND(ISNUMBER(SEARCH(" UAH "," "&SUBSTITUTE($I6,","," ")&" ")),ISNUMBER($L6)),$L6,"") | AL6: =IF(AND(ISNUMBER(SEARCH(" RB "," "&SUBSTITUTE($I6,","," ")&" ")),ISNUMBER($L6)),$L6,"")
A7: IAM-03 | B7: IAM | C7: Identity & Access | D7: Strong / phishing-resistant MFA for privileged users; weak methods (SMS/voice) disabled; number matching on | E7: E8 ML2 requires phishing-resistant MFA for privileged access; SMS/voice are trivially phished or SIM-swapped. | F7: Entra > Authentication methods policy; CA authentication strengths; admin sign-in logs | G7: Admins use FIDO2/passkeys/Windows Hello or certificate; auth-strength CA policy scoped to admin roles; SMS and voice disabled tenant-wide or scoped out. | H7: All admin roles behind phishing-resistant auth strength; SMS/voice off. | I7: MFA | J7: Value-add | K7: 2 | M7: =IF(ISNUMBER(L7),IF(L7<K7,"Gap","OK"),IF(L7="N/A","N/A","")) | P7: =IF(AND(M7="Gap",N7<>"",O7<>""),VLOOKUP(N7&O7,Lists!$H$4:$I$12,2,FALSE()),"") | Q7: =IF(AND(M7="Gap",O7="S",OR(N7="H",N7="M")),"Yes","") | R7: Value-add | S7: =IF(A7="","",IFERROR(IF(OR(VLOOKUP(A7,AutoEvidence!$A$2:$G$400,2,FALSE())="Collected",VLOOKUP(A7,AutoEvidence!$A$2:$G$400,2,FALSE())="Partial"),VLOOKUP(A7,AutoEvidence!$A$2:$G$400,3,FALSE())&" ("&VLOOKUP(A7,AutoEvidence!$A$2:$G$400,2,FALSE())&")",VLOOKUP(A7,AutoEvidence!$A$2:$G$400,2,FALSE())),"")) | T7: =IF(A7="","",IFERROR(VLOOKUP(A7,AutoEvidence!$A$2:$G$400,4,FALSE())&"","")) | AB7: =IF(M7="Gap",1,IF(M7="OK",0,"")) | AC7: =IF(P7<>"",VALUE(RIGHT(P7,1))*1000+ROW(),"") | AD7: =IF(ISNUMBER(L7),MIN(L7,K7),"") | AE7: =IF(AND(ISNUMBER(SEARCH(" PA "," "&SUBSTITUTE($I7,","," ")&" ")),ISNUMBER($L7)),$L7,"") | AF7: =IF(AND(ISNUMBER(SEARCH(" PO "," "&SUBSTITUTE($I7,","," ")&" ")),ISNUMBER($L7)),$L7,"") | AG7: =IF(AND(ISNUMBER(SEARCH(" MFA "," "&SUBSTITUTE($I7,","," ")&" ")),ISNUMBER($L7)),$L7,"") | AH7: =IF(AND(ISNUMBER(SEARCH(" RAP "," "&SUBSTITUTE($I7,","," ")&" ")),ISNUMBER($L7)),$L7,"") | AI7: =IF(AND(ISNUMBER(SEARCH(" AC "," "&SUBSTITUTE($I7,","," ")&" ")),ISNUMBER($L7)),$L7,"") | AJ7: =IF(AND(ISNUMBER(SEARCH(" MAC "," "&SUBSTITUTE($I7,","," ")&" ")),ISNUMBER($L7)),$L7,"") | AK7: =IF(AND(ISNUMBER(SEARCH(" UAH "," "&SUBSTITUTE($I7,","," ")&" ")),ISNUMBER($L7)),$L7,"") | AL7: =IF(AND(ISNUMBER(SEARCH(" RB "," "&SUBSTITUTE($I7,","," ")&" ")),ISNUMBER($L7)),$L7,"")
A8: IAM-04 | B8: IAM | C8: Identity & Access | D8: Legacy authentication blocked (CA block policy; basic auth off in Exchange Online) | E8: Legacy protocols bypass MFA entirely. | F8: CA policy 'Block legacy authentication'; Entra sign-in logs filtered by legacy client apps (30 days) | G8: Block policy On for all users/apps; sign-in log shows zero successful legacy sign-ins in 30 days; SMTP AUTH disabled except documented relays. | H8: Blocked; zero legacy successes in 30 days. | I8: MFA | J8: BAU | K8: 2 | M8: =IF(ISNUMBER(L8),IF(L8<K8,"Gap","OK"),IF(L8="N/A","N/A","")) | P8: =IF(AND(M8="Gap",N8<>"",O8<>""),VLOOKUP(N8&O8,Lists!$H$4:$I$12,2,FALSE()),"") | Q8: =IF(AND(M8="Gap",O8="S",OR(N8="H",N8="M")),"Yes","") | R8: BAU | S8: =IF(A8="","",IFERROR(IF(OR(VLOOKUP(A8,AutoEvidence!$A$2:$G$400,2,FALSE())="Collected",VLOOKUP(A8,AutoEvidence!$A$2:$G$400,2,FALSE())="Partial"),VLOOKUP(A8,AutoEvidence!$A$2:$G$400,3,FALSE())&" ("&VLOOKUP(A8,AutoEvidence!$A$2:$G$400,2,FALSE())&")",VLOOKUP(A8,AutoEvidence!$A$2:$G$400,2,FALSE())),"")) | T8: =IF(A8="","",IFERROR(VLOOKUP(A8,AutoEvidence!$A$2:$G$400,4,FALSE())&"","")) | AB8: =IF(M8="Gap",1,IF(M8="OK",0,"")) | AC8: =IF(P8<>"",VALUE(RIGHT(P8,1))*1000+ROW(),"") | AD8: =IF(ISNUMBER(L8),MIN(L8,K8),"") | AE8: =IF(AND(ISNUMBER(SEARCH(" PA "," "&SUBSTITUTE($I8,","," ")&" ")),ISNUMBER($L8)),$L8,"") | AF8: =IF(AND(ISNUMBER(SEARCH(" PO "," "&SUBSTITUTE($I8,","," ")&" ")),ISNUMBER($L8)),$L8,"") | AG8: =IF(AND(ISNUMBER(SEARCH(" MFA "," "&SUBSTITUTE($I8,","," ")&" ")),ISNUMBER($L8)),$L8,"") | AH8: =IF(AND(ISNUMBER(SEARCH(" RAP "," "&SUBSTITUTE($I8,","," ")&" ")),ISNUMBER($L8)),$L8,"") | AI8: =IF(AND(ISNUMBER(SEARCH(" AC "," "&SUBSTITUTE($I8,","," ")&" ")),ISNUMBER($L8)),$L8,"") | AJ8: =IF(AND(ISNUMBER(SEARCH(" MAC "," "&SUBSTITUTE($I8,","," ")&" ")),ISNUMBER($L8)),$L8,"") | AK8: =IF(AND(ISNUMBER(SEARCH(" UAH "," "&SUBSTITUTE($I8,","," ")&" ")),ISNUMBER($L8)),$L8,"") | AL8: =IF(AND(ISNUMBER(SEARCH(" RB "," "&SUBSTITUTE($I8,","," ")&" ")),ISNUMBER($L8)),$L8,"")
A9: IAM-05 | B9: IAM | C9: Identity & Access | D9: Privileged role hygiene: Global Admin count 2-4, dedicated cloud-only admin accounts, least-privilege roles, PIM/JIT where licensed | E9: Standing global admin on daily-driver accounts is the most common tenant-loss pattern (E8 RAP). | F9: Entra > Roles and administrators; Secure Score 'Designate fewer than 5 global admins'; PIM (P2) | G9: List all privileged role holders; check each is a dedicated account with no mailbox/licence, cloud-only, MFA strong; roles are least privilege; PIM eligible not permanent where P2 exists. | H9: 2-4 GAs; all admins dedicated accounts; least privilege roles; PIM if licensed. | I9: RAP | J9: BAU | K9: 2 | M9: =IF(ISNUMBER(L9),IF(L9<K9,"Gap","OK"),IF(L9="N/A","N/A","")) | P9: =IF(AND(M9="Gap",N9<>"",O9<>""),VLOOKUP(N9&O9,Lists!$H$4:$I$12,2,FALSE()),"") | Q9: =IF(AND(M9="Gap",O9="S",OR(N9="H",N9="M")),"Yes","") | R9: BAU | S9: =IF(A9="","",IFERROR(IF(OR(VLOOKUP(A9,AutoEvidence!$A$2:$G$400,2,FALSE())="Collected",VLOOKUP(A9,AutoEvidence!$A$2:$G$400,2,FALSE())="Partial"),VLOOKUP(A9,AutoEvidence!$A$2:$G$400,3,FALSE())&" ("&VLOOKUP(A9,AutoEvidence!$A$2:$G$400,2,FALSE())&")",VLOOKUP(A9,AutoEvidence!$A$2:$G$400,2,FALSE())),"")) | T9: =IF(A9="","",IFERROR(VLOOKUP(A9,AutoEvidence!$A$2:$G$400,4,FALSE())&"","")) | AB9: =IF(M9="Gap",1,IF(M9="OK",0,"")) | AC9: =IF(P9<>"",VALUE(RIGHT(P9,1))*1000+ROW(),"") | AD9: =IF(ISNUMBER(L9),MIN(L9,K9),"") | AE9: =IF(AND(ISNUMBER(SEARCH(" PA "," "&SUBSTITUTE($I9,","," ")&" ")),ISNUMBER($L9)),$L9,"") | AF9: =IF(AND(ISNUMBER(SEARCH(" PO "," "&SUBSTITUTE($I9,","," ")&" ")),ISNUMBER($L9)),$L9,"") | AG9: =IF(AND(ISNUMBER(SEARCH(" MFA "," "&SUBSTITUTE($I9,","," ")&" ")),ISNUMBER($L9)),$L9,"") | AH9: =IF(AND(ISNUMBER(SEARCH(" RAP "," "&SUBSTITUTE($I9,","," ")&" ")),ISNUMBER($L9)),$L9,"") | AI9: =IF(AND(ISNUMBER(SEARCH(" AC "," "&SUBSTITUTE($I9,","," ")&" ")),ISNUMBER($L9)),$L9,"") | AJ9: =IF(AND(ISNUMBER(SEARCH(" MAC "," "&SUBSTITUTE($I9,","," ")&" ")),ISNUMBER($L9)),$L9,"") | AK9: =IF(AND(ISNUMBER(SEARCH(" UAH "," "&SUBSTITUTE($I9,","," ")&" ")),ISNUMBER($L9)),$L9,"") | AL9: =IF(AND(ISNUMBER(SEARCH(" RB "," "&SUBSTITUTE($I9,","," ")&" ")),ISNUMBER($L9)),$L9,"")
A10: IAM-06 | B10: IAM | C10: Identity & Access | D10: Break-glass accounts: two exist, cloud-only, excluded from CA, credentials vaulted, sign-in alert configured | E10: Lock-out from a CA or MFA outage becomes a P1 without them; unmonitored ones are a backdoor. | F10: Entra users; CA exclusions; alert rule (Entra/Log Analytics/Sentinel or Huntress); CyberArk (if bA-held) | G10: Confirm both accounts, long random passwords stored securely (client vault or CyberArk safe), tested in last 6 months, alert on any sign-in. | H10: Two accounts, vaulted, alerting, tested. | I10: RAP | J10: Value-add | K10: 2 | M10: =IF(ISNUMBER(L10),IF(L10<K10,"Gap","OK"),IF(L10="N/A","N/A","")) | P10: =IF(AND(M10="Gap",N10<>"",O10<>""),VLOOKUP(N10&O10,Lists!$H$4:$I$12,2,FALSE()),"") | Q10: =IF(AND(M10="Gap",O10="S",OR(N10="H",N10="M")),"Yes","") | R10: Value-add | S10: =IF(A10="","",IFERROR(IF(OR(VLOOKUP(A10,AutoEvidence!$A$2:$G$400,2,FALSE())="Collected",VLOOKUP(A10,AutoEvidence!$A$2:$G$400,2,FALSE())="Partial"),VLOOKUP(A10,AutoEvidence!$A$2:$G$400,3,FALSE())&" ("&VLOOKUP(A10,AutoEvidence!$A$2:$G$400,2,FALSE())&")",VLOOKUP(A10,AutoEvidence!$A$2:$G$400,2,FALSE())),"")) | T10: =IF(A10="","",IFERROR(VLOOKUP(A10,AutoEvidence!$A$2:$G$400,4,FALSE())&"","")) | AB10: =IF(M10="Gap",1,IF(M10="OK",0,"")) | AC10: =IF(P10<>"",VALUE(RIGHT(P10,1))*1000+ROW(),"") | AD10: =IF(ISNUMBER(L10),MIN(L10,K10),"") | AE10: =IF(AND(ISNUMBER(SEARCH(" PA "," "&SUBSTITUTE($I10,","," ")&" ")),ISNUMBER($L10)),$L10,"") | AF10: =IF(AND(ISNUMBER(SEARCH(" PO "," "&SUBSTITUTE($I10,","," ")&" ")),ISNUMBER($L10)),$L10,"") | AG10: =IF(AND(ISNUMBER(SEARCH(" MFA "," "&SUBSTITUTE($I10,","," ")&" ")),ISNUMBER($L10)),$L10,"") | AH10: =IF(AND(ISNUMBER(SEARCH(" RAP "," "&SUBSTITUTE($I10,","," ")&" ")),ISNUMBER($L10)),$L10,"") | AI10: =IF(AND(ISNUMBER(SEARCH(" AC "," "&SUBSTITUTE($I10,","," ")&" ")),ISNUMBER($L10)),$L10,"") | AJ10: =IF(AND(ISNUMBER(SEARCH(" MAC "," "&SUBSTITUTE($I10,","," ")&" ")),ISNUMBER($L10)),$L10,"") | AK10: =IF(AND(ISNUMBER(SEARCH(" UAH "," "&SUBSTITUTE($I10,","," ")&" ")),ISNUMBER($L10)),$L10,"") | AL10: =IF(AND(ISNUMBER(SEARCH(" RB "," "&SUBSTITUTE($I10,","," ")&" ")),ISNUMBER($L10)),$L10,"")
A11: IAM-07 | B11: IAM | C11: Identity & Access | D11: Partner access is GDAP (not DAP) with least-privilege roles; bA access via Lighthouse named admin accounts; no shared customer admin accounts in CyberArk | E11: bA policy (KB0012228/KB0012557): named-account audit trail; shared accounts are an audit and insurance finding. | F11: M365 Lighthouse > Tenants > GDAP; Partner Center; CyberArk customer safe | G11: GDAP relationship active with expiry > 90 days, roles scoped; DAP removed; any stored customer-managed admin account has rotation + JIT safe or a plan to remove. | H11: GDAP least privilege; no DAP; no shared standing admin accounts. | I11: RAP | J11: BAU | K11: 2 | M11: =IF(ISNUMBER(L11),IF(L11<K11,"Gap","OK"),IF(L11="N/A","N/A","")) | P11: =IF(AND(M11="Gap",N11<>"",O11<>""),VLOOKUP(N11&O11,Lists!$H$4:$I$12,2,FALSE()),"") | Q11: =IF(AND(M11="Gap",O11="S",OR(N11="H",N11="M")),"Yes","") | R11: BAU | S11: =IF(A11="","",IFERROR(IF(OR(VLOOKUP(A11,AutoEvidence!$A$2:$G$400,2,FALSE())="Collected",VLOOKUP(A11,AutoEvidence!$A$2:$G$400,2,FALSE())="Partial"),VLOOKUP(A11,AutoEvidence!$A$2:$G$400,3,FALSE())&" ("&VLOOKUP(A11,AutoEvidence!$A$2:$G$400,2,FALSE())&")",VLOOKUP(A11,AutoEvidence!$A$2:$G$400,2,FALSE())),"")) | T11: =IF(A11="","",IFERROR(VLOOKUP(A11,AutoEvidence!$A$2:$G$400,4,FALSE())&"","")) | AB11: =IF(M11="Gap",1,IF(M11="OK",0,"")) | AC11: =IF(P11<>"",VALUE(RIGHT(P11,1))*1000+ROW(),"") | AD11: =IF(ISNUMBER(L11),MIN(L11,K11),"") | AE11: =IF(AND(ISNUMBER(SEARCH(" PA "," "&SUBSTITUTE($I11,","," ")&" ")),ISNUMBER($L11)),$L11,"") | AF11: =IF(AND(ISNUMBER(SEARCH(" PO "," "&SUBSTITUTE($I11,","," ")&" ")),ISNUMBER($L11)),$L11,"") | AG11: =IF(AND(ISNUMBER(SEARCH(" MFA "," "&SUBSTITUTE($I11,","," ")&" ")),ISNUMBER($L11)),$L11,"") | AH11: =IF(AND(ISNUMBER(SEARCH(" RAP "," "&SUBSTITUTE($I11,","," ")&" ")),ISNUMBER($L11)),$L11,"") | AI11: =IF(AND(ISNUMBER(SEARCH(" AC "," "&SUBSTITUTE($I11,","," ")&" ")),ISNUMBER($L11)),$L11,"") | AJ11: =IF(AND(ISNUMBER(SEARCH(" MAC "," "&SUBSTITUTE($I11,","," ")&" ")),ISNUMBER($L11)),$L11,"") | AK11: =IF(AND(ISNUMBER(SEARCH(" UAH "," "&SUBSTITUTE($I11,","," ")&" ")),ISNUMBER($L11)),$L11,"") | AL11: =IF(AND(ISNUMBER(SEARCH(" RB "," "&SUBSTITUTE($I11,","," ")&" ")),ISNUMBER($L11)),$L11,"")
A12: IAM-08 | B12: IAM | C12: Identity & Access | D12: Guest and external identity governance: stale guests removed, collaboration settings restricted, access reviews where licensed | E12: Guests accumulate silently and retain access to Teams/SharePoint data indefinitely. | F12: Entra > Users (guest filter, last sign-in); External collaboration settings; Access reviews (P2) | G12: Count guests with no sign-in > 90 days; guest invite setting restricted to admins/members; access reviews or a documented quarterly manual review. | H12: No guest inactive > 90 days; invite restricted; review cadence exists. | J12: Value-add | K12: 2 | M12: =IF(ISNUMBER(L12),IF(L12<K12,"Gap","OK"),IF(L12="N/A","N/A","")) | P12: =IF(AND(M12="Gap",N12<>"",O12<>""),VLOOKUP(N12&O12,Lists!$H$4:$I$12,2,FALSE()),"") | Q12: =IF(AND(M12="Gap",O12="S",OR(N12="H",N12="M")),"Yes","") | R12: Value-add | S12: =IF(A12="","",IFERROR(IF(OR(VLOOKUP(A12,AutoEvidence!$A$2:$G$400,2,FALSE())="Collected",VLOOKUP(A12,AutoEvidence!$A$2:$G$400,2,FALSE())="Partial"),VLOOKUP(A12,AutoEvidence!$A$2:$G$400,3,FALSE())&" ("&VLOOKUP(A12,AutoEvidence!$A$2:$G$400,2,FALSE())&")",VLOOKUP(A12,AutoEvidence!$A$2:$G$400,2,FALSE())),"")) | T12: =IF(A12="","",IFERROR(VLOOKUP(A12,AutoEvidence!$A$2:$G$400,4,FALSE())&"","")) | AB12: =IF(M12="Gap",1,IF(M12="OK",0,"")) | AC12: =IF(P12<>"",VALUE(RIGHT(P12,1))*1000+ROW(),"") | AD12: =IF(ISNUMBER(L12),MIN(L12,K12),"") | AE12: =IF(AND(ISNUMBER(SEARCH(" PA "," "&SUBSTITUTE($I12,","," ")&" ")),ISNUMBER($L12)),$L12,"") | AF12: =IF(AND(ISNUMBER(SEARCH(" PO "," "&SUBSTITUTE($I12,","," ")&" ")),ISNUMBER($L12)),$L12,"") | AG12: =IF(AND(ISNUMBER(SEARCH(" MFA "," "&SUBSTITUTE($I12,","," ")&" ")),ISNUMBER($L12)),$L12,"") | AH12: =IF(AND(ISNUMBER(SEARCH(" RAP "," "&SUBSTITUTE($I12,","," ")&" ")),ISNUMBER($L12)),$L12,"") | AI12: =IF(AND(ISNUMBER(SEARCH(" AC "," "&SUBSTITUTE($I12,","," ")&" ")),ISNUMBER($L12)),$L12,"") | AJ12: =IF(AND(ISNUMBER(SEARCH(" MAC "," "&SUBSTITUTE($I12,","," ")&" ")),ISNUMBER($L12)),$L12,"") | AK12: =IF(AND(ISNUMBER(SEARCH(" UAH "," "&SUBSTITUTE($I12,","," ")&" ")),ISNUMBER($L12)),$L12,"") | AL12: =IF(AND(ISNUMBER(SEARCH(" RB "," "&SUBSTITUTE($I12,","," ")&" ")),ISNUMBER($L12)),$L12,"")
A13: IAM-09 | B13: IAM | C13: Identity & Access | D13: Account lifecycle: stale users/computers disabled, JML (joiner-mover-leaver) process defined, service accounts inventoried with owners | E13: Leavers with live accounts and orphaned service accounts are the quiet way in. | F13: Entra sign-in activity; AD (Get-ADUser/Get-ADComputer LastLogonDate via RDM/N-Central script); SNOW KB for JML | G13: Users no sign-in > 90 days disabled/removed; computers > 90 days disabled; service account register exists (owner, purpose, password age, interactive logon denied). | H13: Stale objects < 2%; JML documented; service account register current. | I13: RAP | J13: BAU | K13: 2 | M13: =IF(ISNUMBER(L13),IF(L13<K13,"Gap","OK"),IF(L13="N/A","N/A","")) | P13: =IF(AND(M13="Gap",N13<>"",O13<>""),VLOOKUP(N13&O13,Lists!$H$4:$I$12,2,FALSE()),"") | Q13: =IF(AND(M13="Gap",O13="S",OR(N13="H",N13="M")),"Yes","") | R13: BAU | S13: =IF(A13="","",IFERROR(IF(OR(VLOOKUP(A13,AutoEvidence!$A$2:$G$400,2,FALSE())="Collected",VLOOKUP(A13,AutoEvidence!$A$2:$G$400,2,FALSE())="Partial"),VLOOKUP(A13,AutoEvidence!$A$2:$G$400,3,FALSE())&" ("&VLOOKUP(A13,AutoEvidence!$A$2:$G$400,2,FALSE())&")",VLOOKUP(A13,AutoEvidence!$A$2:$G$400,2,FALSE())),"")) | T13: =IF(A13="","",IFERROR(VLOOKUP(A13,AutoEvidence!$A$2:$G$400,4,FALSE())&"","")) | AB13: =IF(M13="Gap",1,IF(M13="OK",0,"")) | AC13: =IF(P13<>"",VALUE(RIGHT(P13,1))*1000+ROW(),"") | AD13: =IF(ISNUMBER(L13),MIN(L13,K13),"") | AE13: =IF(AND(ISNUMBER(SEARCH(" PA "," "&SUBSTITUTE($I13,","," ")&" ")),ISNUMBER($L13)),$L13,"") | AF13: =IF(AND(ISNUMBER(SEARCH(" PO "," "&SUBSTITUTE($I13,","," ")&" ")),ISNUMBER($L13)),$L13,"") | AG13: =IF(AND(ISNUMBER(SEARCH(" MFA "," "&SUBSTITUTE($I13,","," ")&" ")),ISNUMBER($L13)),$L13,"") | AH13: =IF(AND(ISNUMBER(SEARCH(" RAP "," "&SUBSTITUTE($I13,","," ")&" ")),ISNUMBER($L13)),$L13,"") | AI13: =IF(AND(ISNUMBER(SEARCH(" AC "," "&SUBSTITUTE($I13,","," ")&" ")),ISNUMBER($L13)),$L13,"") | AJ13: =IF(AND(ISNUMBER(SEARCH(" MAC "," "&SUBSTITUTE($I13,","," ")&" ")),ISNUMBER($L13)),$L13,"") | AK13: =IF(AND(ISNUMBER(SEARCH(" UAH "," "&SUBSTITUTE($I13,","," ")&" ")),ISNUMBER($L13)),$L13,"") | AL13: =IF(AND(ISNUMBER(SEARCH(" RB "," "&SUBSTITUTE($I13,","," ")&" ")),ISNUMBER($L13)),$L13,"")
A14: IAM-10 | B14: IAM | C14: Identity & Access | D14: On-prem AD DS health (if hybrid): supported DC OS, replication clean, FSMO/DNS sane, KRBTGT rotated, recycle bin on, legacy protocols disabled | E14: An unhealthy or unhardened AD undermines every cloud control and is the ransomware pivot point. | F14: RDM session to DC: dcdiag /q, repadmin /replsummary; AD Recycle Bin; KRBTGT pwdLastSet; GPO for SMBv1/NTLMv1/LDAP signing | G14: Zero replication errors; DC OS in support; KRBTGT reset < 180 days (twice, spaced); SMBv1 off; LDAP signing/channel binding required; Protected Users for tier-0 admins. | H14: Healthy replication, supported DCs, KRBTGT < 180 d, legacy protocols off. | I14: RAP, PO | J14: BAU | K14: 2 | M14: =IF(ISNUMBER(L14),IF(L14<K14,"Gap","OK"),IF(L14="N/A","N/A","")) | P14: =IF(AND(M14="Gap",N14<>"",O14<>""),VLOOKUP(N14&O14,Lists!$H$4:$I$12,2,FALSE()),"") | Q14: =IF(AND(M14="Gap",O14="S",OR(N14="H",N14="M")),"Yes","") | R14: BAU | S14: =IF(A14="","",IFERROR(IF(OR(VLOOKUP(A14,AutoEvidence!$A$2:$G$400,2,FALSE())="Collected",VLOOKUP(A14,AutoEvidence!$A$2:$G$400,2,FALSE())="Partial"),VLOOKUP(A14,AutoEvidence!$A$2:$G$400,3,FALSE())&" ("&VLOOKUP(A14,AutoEvidence!$A$2:$G$400,2,FALSE())&")",VLOOKUP(A14,AutoEvidence!$A$2:$G$400,2,FALSE())),"")) | T14: =IF(A14="","",IFERROR(VLOOKUP(A14,AutoEvidence!$A$2:$G$400,4,FALSE())&"","")) | AB14: =IF(M14="Gap",1,IF(M14="OK",0,"")) | AC14: =IF(P14<>"",VALUE(RIGHT(P14,1))*1000+ROW(),"") | AD14: =IF(ISNUMBER(L14),MIN(L14,K14),"") | AE14: =IF(AND(ISNUMBER(SEARCH(" PA "," "&SUBSTITUTE($I14,","," ")&" ")),ISNUMBER($L14)),$L14,"") | AF14: =IF(AND(ISNUMBER(SEARCH(" PO "," "&SUBSTITUTE($I14,","," ")&" ")),ISNUMBER($L14)),$L14,"") | AG14: =IF(AND(ISNUMBER(SEARCH(" MFA "," "&SUBSTITUTE($I14,","," ")&" ")),ISNUMBER($L14)),$L14,"") | AH14: =IF(AND(ISNUMBER(SEARCH(" RAP "," "&SUBSTITUTE($I14,","," ")&" ")),ISNUMBER($L14)),$L14,"") | AI14: =IF(AND(ISNUMBER(SEARCH(" AC "," "&SUBSTITUTE($I14,","," ")&" ")),ISNUMBER($L14)),$L14,"") | AJ14: =IF(AND(ISNUMBER(SEARCH(" MAC "," "&SUBSTITUTE($I14,","," ")&" ")),ISNUMBER($L14)),$L14,"") | AK14: =IF(AND(ISNUMBER(SEARCH(" UAH "," "&SUBSTITUTE($I14,","," ")&" ")),ISNUMBER($L14)),$L14,"") | AL14: =IF(AND(ISNUMBER(SEARCH(" RB "," "&SUBSTITUTE($I14,","," ")&" ")),ISNUMBER($L14)),$L14,"")
A15: IAM-11 | B15: IAM | C15: Identity & Access | D15: Credential policy: Entra Password Protection (incl. on-prem agent), sensible expiry policy, Windows LAPS for local admin passwords | E15: Reused/guessable passwords and shared local admin passwords enable lateral movement (E8 ML2: local admin creds unique and managed). | F15: Entra > Password protection; GPO/Intune LAPS policy; Intune > Devices > Local admin password | G15: Banned password list enforced (hybrid agent on DCs if AD); LAPS deployed to 100% of Windows devices and servers; policy on expiry documented and consistent with MFA posture. | H15: Password Protection on; LAPS on all Windows endpoints and member servers. | I15: RAP | J15: BAU | K15: 2 | M15: =IF(ISNUMBER(L15),IF(L15<K15,"Gap","OK"),IF(L15="N/A","N/A","")) | P15: =IF(AND(M15="Gap",N15<>"",O15<>""),VLOOKUP(N15&O15,Lists!$H$4:$I$12,2,FALSE()),"") | Q15: =IF(AND(M15="Gap",O15="S",OR(N15="H",N15="M")),"Yes","") | R15: BAU | S15: =IF(A15="","",IFERROR(IF(OR(VLOOKUP(A15,AutoEvidence!$A$2:$G$400,2,FALSE())="Collected",VLOOKUP(A15,AutoEvidence!$A$2:$G$400,2,FALSE())="Partial"),VLOOKUP(A15,AutoEvidence!$A$2:$G$400,3,FALSE())&" ("&VLOOKUP(A15,AutoEvidence!$A$2:$G$400,2,FALSE())&")",VLOOKUP(A15,AutoEvidence!$A$2:$G$400,2,FALSE())),"")) | T15: =IF(A15="","",IFERROR(VLOOKUP(A15,AutoEvidence!$A$2:$G$400,4,FALSE())&"","")) | AB15: =IF(M15="Gap",1,IF(M15="OK",0,"")) | AC15: =IF(P15<>"",VALUE(RIGHT(P15,1))*1000+ROW(),"") | AD15: =IF(ISNUMBER(L15),MIN(L15,K15),"") | AE15: =IF(AND(ISNUMBER(SEARCH(" PA "," "&SUBSTITUTE($I15,","," ")&" ")),ISNUMBER($L15)),$L15,"") | AF15: =IF(AND(ISNUMBER(SEARCH(" PO "," "&SUBSTITUTE($I15,","," ")&" ")),ISNUMBER($L15)),$L15,"") | AG15: =IF(AND(ISNUMBER(SEARCH(" MFA "," "&SUBSTITUTE($I15,","," ")&" ")),ISNUMBER($L15)),$L15,"") | AH15: =IF(AND(ISNUMBER(SEARCH(" RAP "," "&SUBSTITUTE($I15,","," ")&" ")),ISNUMBER($L15)),$L15,"") | AI15: =IF(AND(ISNUMBER(SEARCH(" AC "," "&SUBSTITUTE($I15,","," ")&" ")),ISNUMBER($L15)),$L15,"") | AJ15: =IF(AND(ISNUMBER(SEARCH(" MAC "," "&SUBSTITUTE($I15,","," ")&" ")),ISNUMBER($L15)),$L15,"") | AK15: =IF(AND(ISNUMBER(SEARCH(" UAH "," "&SUBSTITUTE($I15,","," ")&" ")),ISNUMBER($L15)),$L15,"") | AL15: =IF(AND(ISNUMBER(SEARCH(" RB "," "&SUBSTITUTE($I15,","," ")&" ")),ISNUMBER($L15)),$L15,"")
A16: IAM-12 | B16: IAM | C16: Identity & Access | D16: Conditional Access baseline: compliant/hybrid-joined device for corporate apps, unsupported platforms blocked, session controls for unmanaged devices, named locations | E16: MFA alone does not stop token theft or access from unmanaged devices. | F16: Entra > Conditional Access (policy list + CA insights workbook); Intune compliance | G16: Policies exist for: require compliant device (or app protection) for M365, block unsupported device platforms, sign-in frequency/no persistent browser for unmanaged; report-only policies not left indefinitely. | H16: Documented CA baseline with the four core policies enabled. | I16: MFA | J16: Value-add | K16: 2 | M16: =IF(ISNUMBER(L16),IF(L16<K16,"Gap","OK"),IF(L16="N/A","N/A","")) | P16: =IF(AND(M16="Gap",N16<>"",O16<>""),VLOOKUP(N16&O16,Lists!$H$4:$I$12,2,FALSE()),"") | Q16: =IF(AND(M16="Gap",O16="S",OR(N16="H",N16="M")),"Yes","") | R16: Value-add | S16: =IF(A16="","",IFERROR(IF(OR(VLOOKUP(A16,AutoEvidence!$A$2:$G$400,2,FALSE())="Collected",VLOOKUP(A16,AutoEvidence!$A$2:$G$400,2,FALSE())="Partial"),VLOOKUP(A16,AutoEvidence!$A$2:$G$400,3,FALSE())&" ("&VLOOKUP(A16,AutoEvidence!$A$2:$G$400,2,FALSE())&")",VLOOKUP(A16,AutoEvidence!$A$2:$G$400,2,FALSE())),"")) | T16: =IF(A16="","",IFERROR(VLOOKUP(A16,AutoEvidence!$A$2:$G$400,4,FALSE())&"","")) | AB16: =IF(M16="Gap",1,IF(M16="OK",0,"")) | AC16: =IF(P16<>"",VALUE(RIGHT(P16,1))*1000+ROW(),"") | AD16: =IF(ISNUMBER(L16),MIN(L16,K16),"") | AE16: =IF(AND(ISNUMBER(SEARCH(" PA "," "&SUBSTITUTE($I16,","," ")&" ")),ISNUMBER($L16)),$L16,"") | AF16: =IF(AND(ISNUMBER(SEARCH(" PO "," "&SUBSTITUTE($I16,","," ")&" ")),ISNUMBER($L16)),$L16,"") | AG16: =IF(AND(ISNUMBER(SEARCH(" MFA "," "&SUBSTITUTE($I16,","," ")&" ")),ISNUMBER($L16)),$L16,"") | AH16: =IF(AND(ISNUMBER(SEARCH(" RAP "," "&SUBSTITUTE($I16,","," ")&" ")),ISNUMBER($L16)),$L16,"") | AI16: =IF(AND(ISNUMBER(SEARCH(" AC "," "&SUBSTITUTE($I16,","," ")&" ")),ISNUMBER($L16)),$L16,"") | AJ16: =IF(AND(ISNUMBER(SEARCH(" MAC "," "&SUBSTITUTE($I16,","," ")&" ")),ISNUMBER($L16)),$L16,"") | AK16: =IF(AND(ISNUMBER(SEARCH(" UAH "," "&SUBSTITUTE($I16,","," ")&" ")),ISNUMBER($L16)),$L16,"") | AL16: =IF(AND(ISNUMBER(SEARCH(" RB "," "&SUBSTITUTE($I16,","," ")&" ")),ISNUMBER($L16)),$L16,"")
A17: IAM-13 | B17: IAM | C17: Identity & Access | D17: Identity Protection / risky sign-in handling (P2): risk policies enabled, risky users remediated, alerts routed to MDR/SOC | E17: Licensed detection that nobody watches is a paid-for gap. | F17: Entra > Protection > Identity Protection (risky users, risk policies); Huntress/Rapid7 alert routing | G17: If P2 licensed: user-risk and sign-in-risk CA policies enabled; risky users list at zero unremediated > 7 days; alerts reach a monitored queue. If not licensed: mark N/A and note in M365-10. | H17: Policies on; no unremediated risky users > 7 days; alerts monitored. | I17: MFA | J17: Value-add | K17: 2 | M17: =IF(ISNUMBER(L17),IF(L17<K17,"Gap","OK"),IF(L17="N/A","N/A","")) | P17: =IF(AND(M17="Gap",N17<>"",O17<>""),VLOOKUP(N17&O17,Lists!$H$4:$I$12,2,FALSE()),"") | Q17: =IF(AND(M17="Gap",O17="S",OR(N17="H",N17="M")),"Yes","") | R17: Value-add | S17: =IF(A17="","",IFERROR(IF(OR(VLOOKUP(A17,AutoEvidence!$A$2:$G$400,2,FALSE())="Collected",VLOOKUP(A17,AutoEvidence!$A$2:$G$400,2,FALSE())="Partial"),VLOOKUP(A17,AutoEvidence!$A$2:$G$400,3,FALSE())&" ("&VLOOKUP(A17,AutoEvidence!$A$2:$G$400,2,FALSE())&")",VLOOKUP(A17,AutoEvidence!$A$2:$G$400,2,FALSE())),"")) | T17: =IF(A17="","",IFERROR(VLOOKUP(A17,AutoEvidence!$A$2:$G$400,4,FALSE())&"","")) | AB17: =IF(M17="Gap",1,IF(M17="OK",0,"")) | AC17: =IF(P17<>"",VALUE(RIGHT(P17,1))*1000+ROW(),"") | AD17: =IF(ISNUMBER(L17),MIN(L17,K17),"") | AE17: =IF(AND(ISNUMBER(SEARCH(" PA "," "&SUBSTITUTE($I17,","," ")&" ")),ISNUMBER($L17)),$L17,"") | AF17: =IF(AND(ISNUMBER(SEARCH(" PO "," "&SUBSTITUTE($I17,","," ")&" ")),ISNUMBER($L17)),$L17,"") | AG17: =IF(AND(ISNUMBER(SEARCH(" MFA "," "&SUBSTITUTE($I17,","," ")&" ")),ISNUMBER($L17)),$L17,"") | AH17: =IF(AND(ISNUMBER(SEARCH(" RAP "," "&SUBSTITUTE($I17,","," ")&" ")),ISNUMBER($L17)),$L17,"") | AI17: =IF(AND(ISNUMBER(SEARCH(" AC "," "&SUBSTITUTE($I17,","," ")&" ")),ISNUMBER($L17)),$L17,"") | AJ17: =IF(AND(ISNUMBER(SEARCH(" MAC "," "&SUBSTITUTE($I17,","," ")&" ")),ISNUMBER($L17)),$L17,"") | AK17: =IF(AND(ISNUMBER(SEARCH(" UAH "," "&SUBSTITUTE($I17,","," ")&" ")),ISNUMBER($L17)),$L17,"") | AL17: =IF(AND(ISNUMBER(SEARCH(" RB "," "&SUBSTITUTE($I17,","," ")&" ")),ISNUMBER($L17)),$L17,"")
A18: IAM-14 | B18: IAM | C18: Identity & Access | D18: SaaS SSO coverage and app consent governance: key apps behind Entra SSO; user consent to unverified apps blocked; admin consent workflow | E18: OAuth consent phishing and orphaned SaaS logins bypass every device and MFA control. | F18: Entra > Enterprise applications; Consent and permissions settings; Secure Score item | G18: User consent set to 'verified publishers, low-impact' or disabled; admin consent workflow enabled with named approvers; top 10 business SaaS apps use SSO. | H18: Consent restricted; workflow on; critical SaaS on SSO. | J18: Value-add | K18: 2 | M18: =IF(ISNUMBER(L18),IF(L18<K18,"Gap","OK"),IF(L18="N/A","N/A","")) | P18: =IF(AND(M18="Gap",N18<>"",O18<>""),VLOOKUP(N18&O18,Lists!$H$4:$I$12,2,FALSE()),"") | Q18: =IF(AND(M18="Gap",O18="S",OR(N18="H",N18="M")),"Yes","") | R18: Value-add | S18: =IF(A18="","",IFERROR(IF(OR(VLOOKUP(A18,AutoEvidence!$A$2:$G$400,2,FALSE())="Collected",VLOOKUP(A18,AutoEvidence!$A$2:$G$400,2,FALSE())="Partial"),VLOOKUP(A18,AutoEvidence!$A$2:$G$400,3,FALSE())&" ("&VLOOKUP(A18,AutoEvidence!$A$2:$G$400,2,FALSE())&")",VLOOKUP(A18,AutoEvidence!$A$2:$G$400,2,FALSE())),"")) | T18: =IF(A18="","",IFERROR(VLOOKUP(A18,AutoEvidence!$A$2:$G$400,4,FALSE())&"","")) | AB18: =IF(M18="Gap",1,IF(M18="OK",0,"")) | AC18: =IF(P18<>"",VALUE(RIGHT(P18,1))*1000+ROW(),"") | AD18: =IF(ISNUMBER(L18),MIN(L18,K18),"") | AE18: =IF(AND(ISNUMBER(SEARCH(" PA "," "&SUBSTITUTE($I18,","," ")&" ")),ISNUMBER($L18)),$L18,"") | AF18: =IF(AND(ISNUMBER(SEARCH(" PO "," "&SUBSTITUTE($I18,","," ")&" ")),ISNUMBER($L18)),$L18,"") | AG18: =IF(AND(ISNUMBER(SEARCH(" MFA "," "&SUBSTITUTE($I18,","," ")&" ")),ISNUMBER($L18)),$L18,"") | AH18: =IF(AND(ISNUMBER(SEARCH(" RAP "," "&SUBSTITUTE($I18,","," ")&" ")),ISNUMBER($L18)),$L18,"") | AI18: =IF(AND(ISNUMBER(SEARCH(" AC "," "&SUBSTITUTE($I18,","," ")&" ")),ISNUMBER($L18)),$L18,"") | AJ18: =IF(AND(ISNUMBER(SEARCH(" MAC "," "&SUBSTITUTE($I18,","," ")&" ")),ISNUMBER($L18)),$L18,"") | AK18: =IF(AND(ISNUMBER(SEARCH(" UAH "," "&SUBSTITUTE($I18,","," ")&" ")),ISNUMBER($L18)),$L18,"") | AL18: =IF(AND(ISNUMBER(SEARCH(" RB "," "&SUBSTITUTE($I18,","," ")&" ")),ISNUMBER($L18)),$L18,"")
A19: M365-01 | B19: M365 | C19: Microsoft 365 & Email Security | D19: Tenant baseline: Microsoft Secure Score tracked, top actions actioned or formally risk-accepted, quarterly M365 Health Report top-3 closed | E19: Handbook expects top-3 priorities per customer per quarter; Secure Score is the shared yardstick with the client. | F19: Defender portal > Secure Score (via Lighthouse); last quarterly M365 Health Report; LOG.md | G19: Record score % and 90-day trend; check last quarter's top-3 status; alternatively-mitigated items marked in portal so they drop off future reports. | H19: Score trending up; last quarter's top-3 closed or re-planned with dates. | J19: BAU | K19: 2 | M19: =IF(ISNUMBER(L19),IF(L19<K19,"Gap","OK"),IF(L19="N/A","N/A","")) | P19: =IF(AND(M19="Gap",N19<>"",O19<>""),VLOOKUP(N19&O19,Lists!$H$4:$I$12,2,FALSE()),"") | Q19: =IF(AND(M19="Gap",O19="S",OR(N19="H",N19="M")),"Yes","") | R19: BAU | S19: =IF(A19="","",IFERROR(IF(OR(VLOOKUP(A19,AutoEvidence!$A$2:$G$400,2,FALSE())="Collected",VLOOKUP(A19,AutoEvidence!$A$2:$G$400,2,FALSE())="Partial"),VLOOKUP(A19,AutoEvidence!$A$2:$G$400,3,FALSE())&" ("&VLOOKUP(A19,AutoEvidence!$A$2:$G$400,2,FALSE())&")",VLOOKUP(A19,AutoEvidence!$A$2:$G$400,2,FALSE())),"")) | T19: =IF(A19="","",IFERROR(VLOOKUP(A19,AutoEvidence!$A$2:$G$400,4,FALSE())&"","")) | AB19: =IF(M19="Gap",1,IF(M19="OK",0,"")) | AC19: =IF(P19<>"",VALUE(RIGHT(P19,1))*1000+ROW(),"") | AD19: =IF(ISNUMBER(L19),MIN(L19,K19),"") | AE19: =IF(AND(ISNUMBER(SEARCH(" PA "," "&SUBSTITUTE($I19,","," ")&" ")),ISNUMBER($L19)),$L19,"") | AF19: =IF(AND(ISNUMBER(SEARCH(" PO "," "&SUBSTITUTE($I19,","," ")&" ")),ISNUMBER($L19)),$L19,"") | AG19: =IF(AND(ISNUMBER(SEARCH(" MFA "," "&SUBSTITUTE($I19,","," ")&" ")),ISNUMBER($L19)),$L19,"") | AH19: =IF(AND(ISNUMBER(SEARCH(" RAP "," "&SUBSTITUTE($I19,","," ")&" ")),ISNUMBER($L19)),$L19,"") | AI19: =IF(AND(ISNUMBER(SEARCH(" AC "," "&SUBSTITUTE($I19,","," ")&" ")),ISNUMBER($L19)),$L19,"") | AJ19: =IF(AND(ISNUMBER(SEARCH(" MAC "," "&SUBSTITUTE($I19,","," ")&" ")),ISNUMBER($L19)),$L19,"") | AK19: =IF(AND(ISNUMBER(SEARCH(" UAH "," "&SUBSTITUTE($I19,","," ")&" ")),ISNUMBER($L19)),$L19,"") | AL19: =IF(AND(ISNUMBER(SEARCH(" RB "," "&SUBSTITUTE($I19,","," ")&" ")),ISNUMBER($L19)),$L19,"")
A20: M365-02 | B20: M365 | C20: Microsoft 365 & Email Security | D20: Email authentication: SPF (single record, < 10 lookups, -all), DKIM on all sending domains and third-party senders, DMARC at quarantine/reject with reporting | E20: Spoofing of the client's own domain drives BEC losses; DMARC p=none is not protection. | F20: mxtoolbox / dmarcian; EXO > DKIM; Mimecast DKIM signing; DNS (EasyDNS) | G20: Check every owned/sending domain: SPF valid and hard-fail, DKIM selectors live (M365 + Mimecast + marketing/ERP senders), DMARC policy and rua address monitored. Note parked domains lacking null SPF/DMARC. | H20: All domains SPF -all, DKIM aligned, DMARC p=quarantine or reject with reports reviewed. | J20: Value-add | K20: 2 | M20: =IF(ISNUMBER(L20),IF(L20<K20,"Gap","OK"),IF(L20="N/A","N/A","")) | P20: =IF(AND(M20="Gap",N20<>"",O20<>""),VLOOKUP(N20&O20,Lists!$H$4:$I$12,2,FALSE()),"") | Q20: =IF(AND(M20="Gap",O20="S",OR(N20="H",N20="M")),"Yes","") | R20: Value-add | S20: =IF(A20="","",IFERROR(IF(OR(VLOOKUP(A20,AutoEvidence!$A$2:$G$400,2,FALSE())="Collected",VLOOKUP(A20,AutoEvidence!$A$2:$G$400,2,FALSE())="Partial"),VLOOKUP(A20,AutoEvidence!$A$2:$G$400,3,FALSE())&" ("&VLOOKUP(A20,AutoEvidence!$A$2:$G$400,2,FALSE())&")",VLOOKUP(A20,AutoEvidence!$A$2:$G$400,2,FALSE())),"")) | T20: =IF(A20="","",IFERROR(VLOOKUP(A20,AutoEvidence!$A$2:$G$400,4,FALSE())&"","")) | AB20: =IF(M20="Gap",1,IF(M20="OK",0,"")) | AC20: =IF(P20<>"",VALUE(RIGHT(P20,1))*1000+ROW(),"") | AD20: =IF(ISNUMBER(L20),MIN(L20,K20),"") | AE20: =IF(AND(ISNUMBER(SEARCH(" PA "," "&SUBSTITUTE($I20,","," ")&" ")),ISNUMBER($L20)),$L20,"") | AF20: =IF(AND(ISNUMBER(SEARCH(" PO "," "&SUBSTITUTE($I20,","," ")&" ")),ISNUMBER($L20)),$L20,"") | AG20: =IF(AND(ISNUMBER(SEARCH(" MFA "," "&SUBSTITUTE($I20,","," ")&" ")),ISNUMBER($L20)),$L20,"") | AH20: =IF(AND(ISNUMBER(SEARCH(" RAP "," "&SUBSTITUTE($I20,","," ")&" ")),ISNUMBER($L20)),$L20,"") | AI20: =IF(AND(ISNUMBER(SEARCH(" AC "," "&SUBSTITUTE($I20,","," ")&" ")),ISNUMBER($L20)),$L20,"") | AJ20: =IF(AND(ISNUMBER(SEARCH(" MAC "," "&SUBSTITUTE($I20,","," ")&" ")),ISNUMBER($L20)),$L20,"") | AK20: =IF(AND(ISNUMBER(SEARCH(" UAH "," "&SUBSTITUTE($I20,","," ")&" ")),ISNUMBER($L20)),$L20,"") | AL20: =IF(AND(ISNUMBER(SEARCH(" RB "," "&SUBSTITUTE($I20,","," ")&" ")),ISNUMBER($L20)),$L20,"")
A21: M365-03 | B21: M365 | C21: Microsoft 365 & Email Security | D21: Inbound mail protection: Mimecast or Defender for Office 365 with impersonation/anti-phish, Safe Links/Attachments (or URL Protect/Attachment Protect), connectors locked to the gateway | E21: Email remains the top delivery channel; an open EXO connector lets attackers bypass the gateway. | F21: Mimecast console; Defender > Email & collaboration > Policies (Preset security policies); EXO inbound connectors | G21: Preset Standard/Strict or equivalent Mimecast policies applied to all users; impersonation protection lists executives and domains; if Mimecast, EXO only accepts mail from Mimecast IPs; enhanced filtering configured. | H21: Gateway policies on for all users; MX bypass closed. | J21: BAU | K21: 2 | M21: =IF(ISNUMBER(L21),IF(L21<K21,"Gap","OK"),IF(L21="N/A","N/A","")) | P21: =IF(AND(M21="Gap",N21<>"",O21<>""),VLOOKUP(N21&O21,Lists!$H$4:$I$12,2,FALSE()),"") | Q21: =IF(AND(M21="Gap",O21="S",OR(N21="H",N21="M")),"Yes","") | R21: BAU | S21: =IF(A21="","",IFERROR(IF(OR(VLOOKUP(A21,AutoEvidence!$A$2:$G$400,2,FALSE())="Collected",VLOOKUP(A21,AutoEvidence!$A$2:$G$400,2,FALSE())="Partial"),VLOOKUP(A21,AutoEvidence!$A$2:$G$400,3,FALSE())&" ("&VLOOKUP(A21,AutoEvidence!$A$2:$G$400,2,FALSE())&")",VLOOKUP(A21,AutoEvidence!$A$2:$G$400,2,FALSE())),"")) | T21: =IF(A21="","",IFERROR(VLOOKUP(A21,AutoEvidence!$A$2:$G$400,4,FALSE())&"","")) | AB21: =IF(M21="Gap",1,IF(M21="OK",0,"")) | AC21: =IF(P21<>"",VALUE(RIGHT(P21,1))*1000+ROW(),"") | AD21: =IF(ISNUMBER(L21),MIN(L21,K21),"") | AE21: =IF(AND(ISNUMBER(SEARCH(" PA "," "&SUBSTITUTE($I21,","," ")&" ")),ISNUMBER($L21)),$L21,"") | AF21: =IF(AND(ISNUMBER(SEARCH(" PO "," "&SUBSTITUTE($I21,","," ")&" ")),ISNUMBER($L21)),$L21,"") | AG21: =IF(AND(ISNUMBER(SEARCH(" MFA "," "&SUBSTITUTE($I21,","," ")&" ")),ISNUMBER($L21)),$L21,"") | AH21: =IF(AND(ISNUMBER(SEARCH(" RAP "," "&SUBSTITUTE($I21,","," ")&" ")),ISNUMBER($L21)),$L21,"") | AI21: =IF(AND(ISNUMBER(SEARCH(" AC "," "&SUBSTITUTE($I21,","," ")&" ")),ISNUMBER($L21)),$L21,"") | AJ21: =IF(AND(ISNUMBER(SEARCH(" MAC "," "&SUBSTITUTE($I21,","," ")&" ")),ISNUMBER($L21)),$L21,"") | AK21: =IF(AND(ISNUMBER(SEARCH(" UAH "," "&SUBSTITUTE($I21,","," ")&" ")),ISNUMBER($L21)),$L21,"") | AL21: =IF(AND(ISNUMBER(SEARCH(" RB "," "&SUBSTITUTE($I21,","," ")&" ")),ISNUMBER($L21)),$L21,"")
A22: M365-04 | B22: M365 | C22: Microsoft 365 & Email Security | D22: Mailbox hygiene: external auto-forwarding blocked, forwarding report clean, mailbox auditing on, shared mailboxes sign-in blocked, inactive licensed mailboxes reviewed | E22: Auto-forward rules are the classic post-compromise persistence; inactive licensed mailboxes are pure waste. | F22: EXO > Outbound spam policy (auto-forward); Mail flow > Auto-forwarded messages report; Get-Mailbox audit; M365 usage reports | G22: Automatic forwarding = Off in outbound spam policy; review forwarding report for rules to external domains; shared mailboxes have sign-in blocked; list mailboxes inactive > 90 days still licensed. | H22: Forwarding blocked; no unexplained external forwards; shared mailbox sign-in blocked. | J22: BAU | K22: 2 | M22: =IF(ISNUMBER(L22),IF(L22<K22,"Gap","OK"),IF(L22="N/A","N/A","")) | P22: =IF(AND(M22="Gap",N22<>"",O22<>""),VLOOKUP(N22&O22,Lists!$H$4:$I$12,2,FALSE()),"") | Q22: =IF(AND(M22="Gap",O22="S",OR(N22="H",N22="M")),"Yes","") | R22: BAU | S22: =IF(A22="","",IFERROR(IF(OR(VLOOKUP(A22,AutoEvidence!$A$2:$G$400,2,FALSE())="Collected",VLOOKUP(A22,AutoEvidence!$A$2:$G$400,2,FALSE())="Partial"),VLOOKUP(A22,AutoEvidence!$A$2:$G$400,3,FALSE())&" ("&VLOOKUP(A22,AutoEvidence!$A$2:$G$400,2,FALSE())&")",VLOOKUP(A22,AutoEvidence!$A$2:$G$400,2,FALSE())),"")) | T22: =IF(A22="","",IFERROR(VLOOKUP(A22,AutoEvidence!$A$2:$G$400,4,FALSE())&"","")) | AB22: =IF(M22="Gap",1,IF(M22="OK",0,"")) | AC22: =IF(P22<>"",VALUE(RIGHT(P22,1))*1000+ROW(),"") | AD22: =IF(ISNUMBER(L22),MIN(L22,K22),"") | AE22: =IF(AND(ISNUMBER(SEARCH(" PA "," "&SUBSTITUTE($I22,","," ")&" ")),ISNUMBER($L22)),$L22,"") | AF22: =IF(AND(ISNUMBER(SEARCH(" PO "," "&SUBSTITUTE($I22,","," ")&" ")),ISNUMBER($L22)),$L22,"") | AG22: =IF(AND(ISNUMBER(SEARCH(" MFA "," "&SUBSTITUTE($I22,","," ")&" ")),ISNUMBER($L22)),$L22,"") | AH22: =IF(AND(ISNUMBER(SEARCH(" RAP "," "&SUBSTITUTE($I22,","," ")&" ")),ISNUMBER($L22)),$L22,"") | AI22: =IF(AND(ISNUMBER(SEARCH(" AC "," "&SUBSTITUTE($I22,","," ")&" ")),ISNUMBER($L22)),$L22,"") | AJ22: =IF(AND(ISNUMBER(SEARCH(" MAC "," "&SUBSTITUTE($I22,","," ")&" ")),ISNUMBER($L22)),$L22,"") | AK22: =IF(AND(ISNUMBER(SEARCH(" UAH "," "&SUBSTITUTE($I22,","," ")&" ")),ISNUMBER($L22)),$L22,"") | AL22: =IF(AND(ISNUMBER(SEARCH(" RB "," "&SUBSTITUTE($I22,","," ")&" ")),ISNUMBER($L22)),$L22,"")
A23: M365-05 | B23: M365 | C23: Microsoft 365 & Email Security | D23: Exchange on-prem residual: no Exchange 2016/2019 (EoS 14 Oct 2025) - migrated to Exchange SE or removed; last-Exchange-server for recipient management handled | E23: Unsupported Exchange is internet-facing, unpatched and directly exploitable. | F23: STACK.md; Orion node list; SNOW CIs; Exchange admin (Get-ExchangeServer) | G23: Identify any on-prem Exchange server, version and CU; internet exposure; plan to Exchange SE (if hybrid management needed) or full decom using the management-tools-only path. | H23: No unsupported Exchange; hybrid management path documented. | I23: PA, PO | J23: Billable | K23: 2 | M23: =IF(ISNUMBER(L23),IF(L23<K23,"Gap","OK"),IF(L23="N/A","N/A","")) | P23: =IF(AND(M23="Gap",N23<>"",O23<>""),VLOOKUP(N23&O23,Lists!$H$4:$I$12,2,FALSE()),"") | Q23: =IF(AND(M23="Gap",O23="S",OR(N23="H",N23="M")),"Yes","") | R23: Billable | S23: =IF(A23="","",IFERROR(IF(OR(VLOOKUP(A23,AutoEvidence!$A$2:$G$400,2,FALSE())="Collected",VLOOKUP(A23,AutoEvidence!$A$2:$G$400,2,FALSE())="Partial"),VLOOKUP(A23,AutoEvidence!$A$2:$G$400,3,FALSE())&" ("&VLOOKUP(A23,AutoEvidence!$A$2:$G$400,2,FALSE())&")",VLOOKUP(A23,AutoEvidence!$A$2:$G$400,2,FALSE())),"")) | T23: =IF(A23="","",IFERROR(VLOOKUP(A23,AutoEvidence!$A$2:$G$400,4,FALSE())&"","")) | AB23: =IF(M23="Gap",1,IF(M23="OK",0,"")) | AC23: =IF(P23<>"",VALUE(RIGHT(P23,1))*1000+ROW(),"") | AD23: =IF(ISNUMBER(L23),MIN(L23,K23),"") | AE23: =IF(AND(ISNUMBER(SEARCH(" PA "," "&SUBSTITUTE($I23,","," ")&" ")),ISNUMBER($L23)),$L23,"") | AF23: =IF(AND(ISNUMBER(SEARCH(" PO "," "&SUBSTITUTE($I23,","," ")&" ")),ISNUMBER($L23)),$L23,"") | AG23: =IF(AND(ISNUMBER(SEARCH(" MFA "," "&SUBSTITUTE($I23,","," ")&" ")),ISNUMBER($L23)),$L23,"") | AH23: =IF(AND(ISNUMBER(SEARCH(" RAP "," "&SUBSTITUTE($I23,","," ")&" ")),ISNUMBER($L23)),$L23,"") | AI23: =IF(AND(ISNUMBER(SEARCH(" AC "," "&SUBSTITUTE($I23,","," ")&" ")),ISNUMBER($L23)),$L23,"") | AJ23: =IF(AND(ISNUMBER(SEARCH(" MAC "," "&SUBSTITUTE($I23,","," ")&" ")),ISNUMBER($L23)),$L23,"") | AK23: =IF(AND(ISNUMBER(SEARCH(" UAH "," "&SUBSTITUTE($I23,","," ")&" ")),ISNUMBER($L23)),$L23,"") | AL23: =IF(AND(ISNUMBER(SEARCH(" RB "," "&SUBSTITUTE($I23,","," ")&" ")),ISNUMBER($L23)),$L23,"")
A24: M365-06 | B24: M365 | C24: Microsoft 365 & Email Security | D24: SharePoint/OneDrive sharing: external sharing scoped, Anyone links off or expiring, default link type internal, unmanaged-device session controls, guest expiry | E24: Over-permissive links are the most common M365 data leakage path and an easy insurer/auditor finding. | F24: SharePoint admin centre > Policies > Sharing; Access control; Secure Score items | G24: Tenant sharing level 'New and existing guests' or tighter; Anyone links disabled or <= 30-day expiry; default link 'People in your organisation'; idle session sign-out and limited access for unmanaged devices. | H24: Sharing restricted per policy; Anyone links off/expiring; defaults internal. | J24: Value-add | K24: 2 | M24: =IF(ISNUMBER(L24),IF(L24<K24,"Gap","OK"),IF(L24="N/A","N/A","")) | P24: =IF(AND(M24="Gap",N24<>"",O24<>""),VLOOKUP(N24&O24,Lists!$H$4:$I$12,2,FALSE()),"") | Q24: =IF(AND(M24="Gap",O24="S",OR(N24="H",N24="M")),"Yes","") | R24: Value-add | S24: =IF(A24="","",IFERROR(IF(OR(VLOOKUP(A24,AutoEvidence!$A$2:$G$400,2,FALSE())="Collected",VLOOKUP(A24,AutoEvidence!$A$2:$G$400,2,FALSE())="Partial"),VLOOKUP(A24,AutoEvidence!$A$2:$G$400,3,FALSE())&" ("&VLOOKUP(A24,AutoEvidence!$A$2:$G$400,2,FALSE())&")",VLOOKUP(A24,AutoEvidence!$A$2:$G$400,2,FALSE())),"")) | T24: =IF(A24="","",IFERROR(VLOOKUP(A24,AutoEvidence!$A$2:$G$400,4,FALSE())&"","")) | AB24: =IF(M24="Gap",1,IF(M24="OK",0,"")) | AC24: =IF(P24<>"",VALUE(RIGHT(P24,1))*1000+ROW(),"") | AD24: =IF(ISNUMBER(L24),MIN(L24,K24),"") | AE24: =IF(AND(ISNUMBER(SEARCH(" PA "," "&SUBSTITUTE($I24,","," ")&" ")),ISNUMBER($L24)),$L24,"") | AF24: =IF(AND(ISNUMBER(SEARCH(" PO "," "&SUBSTITUTE($I24,","," ")&" ")),ISNUMBER($L24)),$L24,"") | AG24: =IF(AND(ISNUMBER(SEARCH(" MFA "," "&SUBSTITUTE($I24,","," ")&" ")),ISNUMBER($L24)),$L24,"") | AH24: =IF(AND(ISNUMBER(SEARCH(" RAP "," "&SUBSTITUTE($I24,","," ")&" ")),ISNUMBER($L24)),$L24,"") | AI24: =IF(AND(ISNUMBER(SEARCH(" AC "," "&SUBSTITUTE($I24,","," ")&" ")),ISNUMBER($L24)),$L24,"") | AJ24: =IF(AND(ISNUMBER(SEARCH(" MAC "," "&SUBSTITUTE($I24,","," ")&" ")),ISNUMBER($L24)),$L24,"") | AK24: =IF(AND(ISNUMBER(SEARCH(" UAH "," "&SUBSTITUTE($I24,","," ")&" ")),ISNUMBER($L24)),$L24,"") | AL24: =IF(AND(ISNUMBER(SEARCH(" RB "," "&SUBSTITUTE($I24,","," ")&" ")),ISNUMBER($L24)),$L24,"")
A25: M365-07 | B25: M365 | C25: Microsoft 365 & Email Security | D25: Teams governance: external access/federation and guest access deliberate, meeting policies (anonymous join, lobby), third-party app policies, team sprawl managed | E25: Open federation enables Teams-based phishing; uncontrolled apps and guests expand the attack surface. | F25: Teams admin centre > Users > External access; Guest access; Meetings > Meeting policies; Teams apps > Permission policies | G25: Federation allow-listed or blocked for known-bad; anonymous users held in lobby; app permission policy blocks unknown third-party apps; team creation governance or expiry policy exists. | H25: Deliberate, documented settings; no 'allow all' defaults left unreviewed. | J25: Value-add | K25: 2 | M25: =IF(ISNUMBER(L25),IF(L25<K25,"Gap","OK"),IF(L25="N/A","N/A","")) | P25: =IF(AND(M25="Gap",N25<>"",O25<>""),VLOOKUP(N25&O25,Lists!$H$4:$I$12,2,FALSE()),"") | Q25: =IF(AND(M25="Gap",O25="S",OR(N25="H",N25="M")),"Yes","") | R25: Value-add | S25: =IF(A25="","",IFERROR(IF(OR(VLOOKUP(A25,AutoEvidence!$A$2:$G$400,2,FALSE())="Collected",VLOOKUP(A25,AutoEvidence!$A$2:$G$400,2,FALSE())="Partial"),VLOOKUP(A25,AutoEvidence!$A$2:$G$400,3,FALSE())&" ("&VLOOKUP(A25,AutoEvidence!$A$2:$G$400,2,FALSE())&")",VLOOKUP(A25,AutoEvidence!$A$2:$G$400,2,FALSE())),"")) | T25: =IF(A25="","",IFERROR(VLOOKUP(A25,AutoEvidence!$A$2:$G$400,4,FALSE())&"","")) | AB25: =IF(M25="Gap",1,IF(M25="OK",0,"")) | AC25: =IF(P25<>"",VALUE(RIGHT(P25,1))*1000+ROW(),"") | AD25: =IF(ISNUMBER(L25),MIN(L25,K25),"") | AE25: =IF(AND(ISNUMBER(SEARCH(" PA "," "&SUBSTITUTE($I25,","," ")&" ")),ISNUMBER($L25)),$L25,"") | AF25: =IF(AND(ISNUMBER(SEARCH(" PO "," "&SUBSTITUTE($I25,","," ")&" ")),ISNUMBER($L25)),$L25,"") | AG25: =IF(AND(ISNUMBER(SEARCH(" MFA "," "&SUBSTITUTE($I25,","," ")&" ")),ISNUMBER($L25)),$L25,"") | AH25: =IF(AND(ISNUMBER(SEARCH(" RAP "," "&SUBSTITUTE($I25,","," ")&" ")),ISNUMBER($L25)),$L25,"") | AI25: =IF(AND(ISNUMBER(SEARCH(" AC "," "&SUBSTITUTE($I25,","," ")&" ")),ISNUMBER($L25)),$L25,"") | AJ25: =IF(AND(ISNUMBER(SEARCH(" MAC "," "&SUBSTITUTE($I25,","," ")&" ")),ISNUMBER($L25)),$L25,"") | AK25: =IF(AND(ISNUMBER(SEARCH(" UAH "," "&SUBSTITUTE($I25,","," ")&" ")),ISNUMBER($L25)),$L25,"") | AL25: =IF(AND(ISNUMBER(SEARCH(" RB "," "&SUBSTITUTE($I25,","," ")&" ")),ISNUMBER($L25)),$L25,"")
A26: M365-08 | B26: M365 | C26: Microsoft 365 & Email Security | D26: Data protection: retention policies for Exchange/SharePoint/Teams, DLP baseline (AU PII/TFN/credit card), sensitivity labels where licensed, audit log retention | E26: Retention is not backup, but its absence is a legal/regulatory exposure; DLP catches the accidental send. | F26: Purview > Data lifecycle management; DLP policies; Information protection; Audit retention policies | G26: At least one retention policy per workload aligned to the client's obligations; DLP policy in test-with-notifications or enforce for AU financial/PII templates; labels published if E3/E5/BP. | H26: Retention + baseline DLP in place and documented. | J26: Value-add | K26: 2 | M26: =IF(ISNUMBER(L26),IF(L26<K26,"Gap","OK"),IF(L26="N/A","N/A","")) | P26: =IF(AND(M26="Gap",N26<>"",O26<>""),VLOOKUP(N26&O26,Lists!$H$4:$I$12,2,FALSE()),"") | Q26: =IF(AND(M26="Gap",O26="S",OR(N26="H",N26="M")),"Yes","") | R26: Value-add | S26: =IF(A26="","",IFERROR(IF(OR(VLOOKUP(A26,AutoEvidence!$A$2:$G$400,2,FALSE())="Collected",VLOOKUP(A26,AutoEvidence!$A$2:$G$400,2,FALSE())="Partial"),VLOOKUP(A26,AutoEvidence!$A$2:$G$400,3,FALSE())&" ("&VLOOKUP(A26,AutoEvidence!$A$2:$G$400,2,FALSE())&")",VLOOKUP(A26,AutoEvidence!$A$2:$G$400,2,FALSE())),"")) | T26: =IF(A26="","",IFERROR(VLOOKUP(A26,AutoEvidence!$A$2:$G$400,4,FALSE())&"","")) | AB26: =IF(M26="Gap",1,IF(M26="OK",0,"")) | AC26: =IF(P26<>"",VALUE(RIGHT(P26,1))*1000+ROW(),"") | AD26: =IF(ISNUMBER(L26),MIN(L26,K26),"") | AE26: =IF(AND(ISNUMBER(SEARCH(" PA "," "&SUBSTITUTE($I26,","," ")&" ")),ISNUMBER($L26)),$L26,"") | AF26: =IF(AND(ISNUMBER(SEARCH(" PO "," "&SUBSTITUTE($I26,","," ")&" ")),ISNUMBER($L26)),$L26,"") | AG26: =IF(AND(ISNUMBER(SEARCH(" MFA "," "&SUBSTITUTE($I26,","," ")&" ")),ISNUMBER($L26)),$L26,"") | AH26: =IF(AND(ISNUMBER(SEARCH(" RAP "," "&SUBSTITUTE($I26,","," ")&" ")),ISNUMBER($L26)),$L26,"") | AI26: =IF(AND(ISNUMBER(SEARCH(" AC "," "&SUBSTITUTE($I26,","," ")&" ")),ISNUMBER($L26)),$L26,"") | AJ26: =IF(AND(ISNUMBER(SEARCH(" MAC "," "&SUBSTITUTE($I26,","," ")&" ")),ISNUMBER($L26)),$L26,"") | AK26: =IF(AND(ISNUMBER(SEARCH(" UAH "," "&SUBSTITUTE($I26,","," ")&" ")),ISNUMBER($L26)),$L26,"") | AL26: =IF(AND(ISNUMBER(SEARCH(" RB "," "&SUBSTITUTE($I26,","," ")&" ")),ISNUMBER($L26)),$L26,"")
